Workbook

Sheet Business Problem
A1: "What factors are associated with employee attrition, which employee groups are at greatest risk, and how can People Analytics help the organisation take proactive action?"
A6: "How would you approach building an attrition-risk model?"
A8: You could eventually answer:
A10: "I'd start by defining the business problem rather than immediately choosing a model. I'd first understand whether the organisation is trying to reduce voluntary attrition overall or address a specific population or capability risk. I'd then validate and prepare the employee data, analyse historical attrition patterns and identify potential drivers across factors such as tenure, engagement, compensation, progression and workforce characteristics.
A15: I'd establish a baseline and then develop a predictive model to identify employees or populations with elevated risk. I'd validate the model carefully and, importantly, focus on interpretability because the output needs to support responsible people decisions. I'd then translate the results into actionable insights for HR and managers rather than simply giving them a risk score. Finally, I'd measure whether interventions actually reduce attrition over time."

Sheet Expectation
A1: For a senior People Analytics role, I'd actually expect you to first show something like:
A3: Overall attrition rate
A5: → Which groups are leaving?
A7: → What factors appear associated with attrition?
A9: → Can we predict who is at higher risk?
A11: → What should HR do about it?

Sheet Practical & Solution Workflow
A1: Our practical workflow
A3: We'll work through:
A5: 1. Define the business question
A6: 2. Explore the workforce data
A7: 3. Identify the target variable — Attrition
A8: 4. Prepare and clean the data
A9: 5. Explore drivers of attrition
A10: 6. Build a baseline model
A11: 7. Build a predictive model
A12: 8. Evaluate model performance
A13: 9. Interpret the key attrition drivers
A14: 10. Create an attrition-risk dashboard
... A24: 4. Actionable — What should HR do about it?

Sheet Dashboard 1_Descriptive  Leave
B3: LEAVERS DASHBOARD — WHO LEFT?
C5: ='Dashboard Pivots'!B5 -> 851 | F5: ='Dashboard Pivots'!B10 -> 149 | I5: ='Dashboard Pivots'!C16 -> 0.149 | O5: ='Dashboard Pivots'!D6 -> 4.5073826
C6: Headcount | F6: No of Leavers | I6: Attrition Rate | N6: Average Tenure of Leavers
B39: The Leavers Dashboard provides a profile of the 149 employees who exited the organisation, highlighting where leavers are concentrated across department, age, tenure, job level, country and performance. It helps identify the characteristics and workforce segments contributing most to overall employee turnover.

Sheet Dashboard 2_Attrition Analysis
B2: ATTRITION DASHBOARD — WHERE IS THE RISK HIGHEST?
B41: The Attrition Dashboard examines the 14.9% overall attrition rate across key workforce segments, identifying areas where employees are leaving at disproportionately higher rates. It highlights variation in attrition by department, gender, age, tenure, job level and country, helping to identify priority populations for further investigation and retention action.

Sheet Dashboard 3_Diagnostic Drivers
B2: DIAGNOSTIC ATTRITION DASHBOARD — WHAT IS ASSOCIATED WITH EMPLOYEE ATTRITION?
Z19: S
B29: The Diagnostic Dashboard shows that attrition is concentrated among employees with low engagement score, lower compensation positioning, longer periods since salary increases,limited career progression and overtime.

Sheet Dashboard 4_Predictive Attritio
B2: PREDICTIVE ATTRITION DASHBOARD — WHO IS MOST LIKELY TO LEAVE?
B4: Model Performance
B5: ='Predictive Pivots'!C7 -> 0.728 | F5: ='Predictive Pivots'!C8 -> 0.1127 | J5: ='Predictive Pivots'!C9 -> 0.149 | N5: ='Predictive Pivots'!C10 -> 1000
B6: ='Predictive Pivots'!B7 -> ROC-AUC | F6: ='Predictive Pivots'!B8 -> Brier Score | J6: ='Predictive Pivots'!B9 -> Overall Attrition | N6: ='Predictive Pivots'!B10 -> Employees
B7: Model Discrimination | F7: Probability accuracy | J7: 149 of 1000 employees | N7: Development dataset
B46: Logistic regression was used to estimate employee attrition probability. Categorical variables were dummy encoded using defined reference categories. Model coefficients were estimated using Excel Solver by maximising log-likelihood. Model development performance: ROC-AUC 0.728; Brier Score 0.1127.
B50: Key insight:The highest-risk 10% of employees contains 31.5% of historical leavers, increasing to 48.3% within the top 20%. This indicates that the model concentrates a disproportionately large share of leavers toward the top of its risk ranking.
B55: Slide 0: Methodology & Model Setup (The Foundation)
B56: Objective: Build a data-driven system to identify individual employee attrition risk and uncover key turnover drivers.
B57: The Engine: Built a custom Logistic Regression Model using Maximum Likelihood Estimation (MLE) optimization directly within Excel.
B58: Data Processing: Evaluated a comprehensive mix of continuous numbers (Age, Tenure, Salary) and categorical text fields (Departments, Role, Country).
B59: Reference Baselines: To prevent mathematical redundancy, standard reference groups were systematically dropped. All resulting insights are measured as a direct contrast to our Baseline Employee Profile:
B60: Gender / Department: Male / Operations
B61: Country / Job Level: United Kingdom / Professional
B62: Work Type / Performance: Hybrid Arrangement / Meets Expectations
B64: 🎛️ How to Handle the Presentation
B65: When you present Slide 0, use it to build immediate credibility with your audience before showing the risks. You can explain it like this:
... B100: Answer: "Absolutely. The underlying math of Logistic Regression is identical whether executed in Python, R, or Excel. We verified the model using a Brier Score, which returned a 0.11271. Since 0.25 represents random guessing and 0.00 is mathematical perfection, a score of 0.11 mathematically proves that this Excel configuration has captured highly stable, genuine operational patterns."

Sheet Predictive Pivots
B2: A. Model performance — top row
B4: Use KPI cards:
I5: Row Labels | J5: Count of Age | K5: Sum of Leaver flag | M5: Row Labels | N5: Sum of Leaver flag | P5: Top 10 | S5: Top 20 | V5: Top 30 | Y5: Top 40 | AB5: Top 50
B6: KPI | C6: Value | I6: High | J6: 148 | K6: 33 | L6: 1 | M6: 0.80396423 | N6: 0 | P6: 0.80396423 | Q6: 0 | S6: 0.80396423 | T6: 0 | V6: 0.80396423 | W6: 0 | Y6: 0.80396423 | Z6: 0 | AB6: 0.80396423 | AC6: 0
B7: ROC-AUC | C7: 0.728 | I7: Low | J7: 437 | K7: 30 | L7: 2 | M7: 0.77735127 | N7: 1 | P7: 0.77735127 | Q7: 1 | S7: 0.77735127 | T7: 1 | V7: 0.77735127 | W7: 1 | Y7: 0.77735127 | Z7: 1 | AB7: 0.77735127 | AC7: 1
B8: Brier Score | C8: 0.1127 | I8: Moderate | J8: 313 | K8: 38 | L8: 3 | M8: 0.63332627 | N8: 1 | P8: 0.63332627 | Q8: 1 | S8: 0.63332627 | T8: 1 | V8: 0.63332627 | W8: 1 | Y8: 0.63332627 | Z8: 1 | AB8: 0.63332627 | AC8: 1
B9: Overall Attrition | C9: 0.149 | I9: Very High | J9: 102 | K9: 48 | L9: 4 | M9: 0.62273774 | N9: 1 | P9: 0.62273774 | Q9: 1 | S9: 0.62273774 | T9: 1 | V9: 0.62273774 | W9: 1 | Y9: 0.62273774 | Z9: 1 | AB9: 0.62273774 | AC9: 1
B10: Employees | C10: 1000 | I10: Grand Total | J10: 1000 | K10: 149 | L10: 5 | M10: 0.61475339 | N10: 0 | P10: 0.61475339 | Q10: 0 | S10: 0.61475339 | T10: 0 | V10: 0.61475339 | W10: 0 | Y10: 0.61475339 | Z10: 0 | AB10: 0.61475339 | AC10: 0
L11: 6 | M11: 0.5909025 | N11: 0 | P11: 0.5909025 | Q11: 0 | S11: 0.5909025 | T11: 0 | V11: 0.5909025 | W11: 0 | Y11: 0.5909025 | Z11: 0 | AB11: 0.5909025 | AC11: 0
L12: 7 | M12: 0.58939698 | N12: 1 | P12: 0.58939698 | Q12: 1 | S12: 0.58939698 | T12: 1 | V12: 0.58939698 | W12: 1 | Y12: 0.58939698 | Z12: 1 | AB12: 0.58939698 | AC12: 1
L13: 8 | M13: 0.58302494 | N13: 1 | P13: 0.58302494 | Q13: 1 | S13: 0.58302494 | T13: 1 | V13: 0.58302494 | W13: 1 | Y13: 0.58302494 | Z13: 1 | AB13: 0.58302494 | AC13: 1
B14: Predicted Probability | C14: Risk band | D14: Employees | E14: Leavers | F14: Actual Attrition | G14: Lift | L14: 9 | M14: 0.56549404 | N14: 1 | P14: 0.56549404 | Q14: 1 | S14: 0.56549404 | T14: 1 | V14: 0.56549404 | W14: 1 | Y14: 0.56549404 | Z14: 1 | AB14: 0.56549404 | AC14: 1
B15: <10% | C15: Low | D15: 437 | E15: 30 | F15: =E15/D15 -> 0.068649886 | G15: =F15/$F$19 -> 0.46073749 | L15: 10 | M15: 0.56221316 | N15: 1 | P15: 0.56221316 | Q15: 1 | S15: 0.56221316 | T15: 1 | V15: 0.56221316 | W15: 1 | Y15: 0.56221316 | Z15: 1 | AB15: 0.56221316 | AC15: 1
B16: 10%-<20% | C16: Moderate | D16: 313 | E16: 38 | F16: =E16/D16 -> 0.12140575 | G16: =F16/$F$19 -> 0.8148037 | L16: 11 | M16: 0.5578065 | N16: 1 | P16: 0.5578065 | Q16: 1 | S16: 0.5578065 | T16: 1 | V16: 0.5578065 | W16: 1 | Y16: 0.5578065 | Z16: 1 | AB16: 0.5578065 | AC16: 1
B17: 20%-<30% | C17: High | D17: 148 | E17: 33 | F17: =E17/D17 -> 0.22297297 | G17: =F17/$F$19 -> 1.4964629 | L17: 12 | M17: 0.54293268 | N17: 0 | P17: 0.54293268 | Q17: 0 | S17: 0.54293268 | T17: 0 | V17: 0.54293268 | W17: 0 | Y17: 0.54293268 | Z17: 0 | AB17: 0.54293268 | AC17: 0
B18: >=30% | C18: Very high | D18: 102 | E18: 48 | F18: =E18/D18 -> 0.47058824 | G18: =F18/$F$19 -> 3.1583103 | L18: 13 | M18: 0.53610589 | N18: 0 | P18: 0.53610589 | Q18: 0 | S18: 0.53610589 | T18: 0 | V18: 0.53610589 | W18: 0 | Y18: 0.53610589 | Z18: 0 | AB18: 0.53610589 | AC18: 0
C19: Total | D19: =SUM(D15:D18) -> 1000 | E19: =SUM(E15:E18) -> 149 | F19: =E19/D19 -> 0.149 | G19: =F19/$F$19 -> 1 | I19: Risk | J19: (Multiple Items) | L19: 14 | M19: 0.52092307 | N19: 0 | P19: 0.52092307 | Q19: 0 | S19: 0.52092307 | T19: 0 | V19: 0.52092307 | W19: 0 | Y19: 0.52092307 | Z19: 0 | AB19: 0.52092307 | AC19: 0
L20: 15 | M20: 0.51757816 | N20: 0 | P20: 0.51757816 | Q20: 0 | S20: 0.51757816 | T20: 0 | V20: 0.51757816 | W20: 0 | Y20: 0.51757816 | Z20: 0 | AB20: 0.51757816 | AC20: 0
B21: Risk band | C21: Employees | D21: % Workforce | I21: Row Labels | J21: Employees | L21: 16 | M21: 0.51282052 | N21: 0 | P21: 0.51282052 | Q21: 0 | S21: 0.51282052 | T21: 0 | V21: 0.51282052 | W21: 0 | Y21: 0.51282052 | Z21: 0 | AB21: 0.51282052 | AC21: 0
B22: Low | C22: 437 | D22: =C22/$C$26 -> 0.437 | I22: Finance | J22: 44 | L22: 17 | M22: 0.51255153 | N22: 1 | P22: 0.51255153 | Q22: 1 | S22: 0.51255153 | T22: 1 | V22: 0.51255153 | W22: 1 | Y22: 0.51255153 | Z22: 1 | AB22: 0.51255153 | AC22: 1
B23: Moderate | C23: 313 | D23: =C23/$C$26 -> 0.313 | I23: IT | J23: 40 | L23: 18 | M23: 0.50933054 | N23: 0 | P23: 0.50933054 | Q23: 0 | S23: 0.50933054 | T23: 0 | V23: 0.50933054 | W23: 0 | Y23: 0.50933054 | Z23: 0 | AB23: 0.50933054 | AC23: 0
B24: High | C24: 148 | D24: =C24/$C$26 -> 0.148 | I24: Operations | J24: 39 | L24: 19 | M24: 0.48949508 | N24: 1 | P24: 0.48949508 | Q24: 1 | S24: 0.48949508 | T24: 1 | V24: 0.48949508 | W24: 1 | Y24: 0.48949508 | Z24: 1 | AB24: 0.48949508 | AC24: 1
B25: Very High | C25: 102 | D25: =C25/$C$26 -> 0.102 | I25: Claims | J25: 38 | L25: 20 | M25: 0.4801273 | N25: 1 | P25: 0.4801273 | Q25: 1 | S25: 0.4801273 | T25: 1 | V25: 0.4801273 | W25: 1 | Y25: 0.4801273 | Z25: 1 | AB25: 0.4801273 | AC25: 1
B26: Total | C26: 1000 | D26: =C26/$C$26 -> 1 | I26: Sales | J26: 36 | L26: 21 | M26: 0.47561535 | N26: 1 | P26: 0.47561535 | Q26: 1 | S26: 0.47561535 | T26: 1 | V26: 0.47561535 | W26: 1 | Y26: 0.47561535 | Z26: 1 | AB26: 0.47561535 | AC26: 1
I27: HR | J27: 26 | L27: 22 | M27: 0.47045928 | N27: 0 | P27: 0.47045928 | Q27: 0 | S27: 0.47045928 | T27: 0 | V27: 0.47045928 | W27: 0 | Y27: 0.47045928 | Z27: 0 | AB27: 0.47045928 | AC27: 0
I28: Marketing | J28: 16 | L28: 23 | M28: 0.47033961 | N28: 1 | P28: 0.47033961 | Q28: 1 | S28: 0.47033961 | T28: 1 | V28: 0.47033961 | W28: 1 | Y28: 0.47033961 | Z28: 1 | AB28: 0.47033961 | AC28: 1
I29: Underwriting | J29: 11 | L29: 24 | M29: 0.46656345 | N29: 1 | P29: 0.46656345 | Q29: 1 | S29: 0.46656345 | T29: 1 | V29: 0.46656345 | W29: 1 | Y29: 0.46656345 | Z29: 1 | AB29: 0.46656345 | AC29: 1
B30: Employees Targeted | C30: Leavers Captured | D30: % of Leavers Captured | E30: Lift | I30: Grand Total | J30: 250 | L30: 25 | M30: 0.45997489 | N30: 1 | P30: 0.45997489 | Q30: 1 | S30: 0.45997489 | T30: 1 | V30: 0.45997489 | W30: 1 | Y30: 0.45997489 | Z30: 1 | AB30: 0.45997489 | AC30: 1
B31: Top 10% | C31: 47 | D31: =C31/149 -> 0.31543624 | L31: 26 | M31: 0.45753775 | N31: 0 | P31: 0.45753775 | Q31: 0 | S31: 0.45753775 | T31: 0 | V31: 0.45753775 | W31: 0 | Y31: 0.45753775 | Z31: 0 | AB31: 0.45753775 | AC31: 0
B32: Top 20% | C32: 72 | D32: =C32/149 -> 0.48322148 | L32: 27 | M32: 0.45085488 | N32: 1 | P32: 0.45085488 | Q32: 1 | S32: 0.45085488 | T32: 1 | V32: 0.45085488 | W32: 1 | Y32: 0.45085488 | Z32: 1 | AB32: 0.45085488 | AC32: 1
B33: Top 30% | C33: 88 | D33: =C33/149 -> 0.59060403 | L33: 28 | M33: 0.44209629 | N33: 1 | P33: 0.44209629 | Q33: 1 | S33: 0.44209629 | T33: 1 | V33: 0.44209629 | W33: 1 | Y33: 0.44209629 | Z33: 1 | AB33: 0.44209629 | AC33: 1
B34: Top 40% | C34: 98 | D34: =C34/149 -> 0.65771812 | I34: Risk | J34: (Multiple Items) | L34: 29 | M34: 0.4390298 | N34: 0 | P34: 0.4390298 | Q34: 0 | S34: 0.4390298 | T34: 0 | V34: 0.4390298 | W34: 0 | Y34: 0.4390298 | Z34: 0 | AB34: 0.4390298 | AC34: 0
B35: Top 50% | C35: 114 | D35: =C35/149 -> 0.76510067 | L35: 30 | M35: 0.43696886 | N35: 0 | P35: 0.43696886 | Q35: 0 | S35: 0.43696886 | T35: 0 | V35: 0.43696886 | W35: 0 | Y35: 0.43696886 | Z35: 0 | AB35: 0.43696886 | AC35: 0
I36: Row Labels | J36: Employees | L36: 31 | M36: 0.43114236 | N36: 0 | P36: 0.43114236 | Q36: 0 | S36: 0.43114236 | T36: 0 | V36: 0.43114236 | W36: 0 | Y36: 0.43114236 | Z36: 0 | AB36: 0.43114236 | AC36: 0
I37: UK | J37: 88 | L37: 32 | M37: 0.42780587 | N37: 1 | P37: 0.42780587 | Q37: 1 | S37: 0.42780587 | T37: 1 | V37: 0.42780587 | W37: 1 | Y37: 0.42780587 | Z37: 1 | AB37: 0.42780587 | AC37: 1
I38: US | J38: 60 | L38: 33 | M38: 0.42240782 | N38: 1 | P38: 0.42240782 | Q38: 1 | S38: 0.42240782 | T38: 1 | V38: 0.42240782 | W38: 1 | Y38: 0.42240782 | Z38: 1 | AB38: 0.42240782 | AC38: 1
I39: Canada | J39: 48 | L39: 34 | M39: 0.41836543 | N39: 0 | P39: 0.41836543 | Q39: 0 | S39: 0.41836543 | T39: 0 | V39: 0.41836543 | W39: 0 | Y39: 0.41836543 | Z39: 0 | AB39: 0.41836543 | AC39: 0
I40: Singapore | J40: 23 | L40: 35 | M40: 0.41327334 | N40: 1 | P40: 0.41327334 | Q40: 1 | S40: 0.41327334 | T40: 1 | V40: 0.41327334 | W40: 1 | Y40: 0.41327334 | Z40: 1 | AB40: 0.41327334 | AC40: 1
I41: Ireland | J41: 20 | L41: 36 | M41: 0.41148355 | N41: 0 | P41: 0.41148355 | Q41: 0 | S41: 0.41148355 | T41: 0 | V41: 0.41148355 | W41: 0 | Y41: 0.41148355 | Z41: 0 | AB41: 0.41148355 | AC41: 0
I42: Germany | J42: 11 | L42: 37 | M42: 0.41126199 | N42: 0 | P42: 0.41126199 | Q42: 0 | S42: 0.41126199 | T42: 0 | V42: 0.41126199 | W42: 0 | Y42: 0.41126199 | Z42: 0 | AB42: 0.41126199 | AC42: 0
...

Sheet Launch of Risk Calculator
A1: Subject: Launch: Data-Driven Attrition Risk Calculator & User Guide
A2: Team,
A3: As part of our commitment to proactive talent management, we are officially launching our new Data-Driven Attrition Risk Calculator.
A4: Built directly within Excel using historical company data, this tool moves us away from guesswork. It allows HR Business Partners to input an employee’s profile and instantly generate an individual 0% to 100% Flight Risk Probability Score.
A5: The calculator tab is now active in our workforce planning file. Please review the simple user guide below to ensure your evaluations are mathematically accurate.
A7: 📊 Attrition Risk Calculator: Manager User Guide
A8: This interactive tool uses our verified predictive model (Brier Score: 0.11272) to estimate an employee's flight risk relative to our company baseline turnover rate of 15%. Use this data to drive proactive career conversations and targeted retention efforts.
A9: 🛠️ How to Input Employee Data
A10: 1. Numeric Fields: Enter exact values in the input column. Keep values realistic (e.g., Compa-Ratio as a decimal like 0.95, Age between 18 and 100).
A11: 2. Dropdown Selectors: Choose the single matching option for Department, Country, Performance, Job Level, and Work Setup.
A12: 3. Security Notice: All mathematical weight matrices and conversion formulas are permanently locked. You only need to modify the open input blocks.
A13: 🚨 Interpreting the Risk Tiers & Strategic Actions
... A35: Workforce Analytics & HR Strategy

Sheet Live Individual Calculator 
A1: *Enter a 1 (Yes) or 0 (No) for the binary encoded rows based on your exact definitions (e.g., if they work overtime, enter 1 because No Overtime = 0), ( if no promotion, enter 0 because Promotion = 1).
E2: =EXP(SUMPRODUCT(B5:B38, C5:C38)) / (1 + EXP(SUMPRODUCT(B5:B38, C5:C38))) -> 0.74846182
A4: Variables | B4: Weights | C4: Math Bridge | D4: Manager Interaction Input Zone | E4: =IF(E2 > 0.3, "🚨 HIGH RISK: Strategic Stay-Interview", IF(E2 > 0.1, "⚠️ MEDIUM RISK: Manager Check-in", "✅ LOW RISK: Standard Retention")) -> 🚨 HIGH RISK: Strategic Stay-Interview
A5: Intercept | B5: -0.87567091 | C5: 1
A6: Age | B6: -0.0096127547 | C6: =D6 -> 32 | D6: 32 | E6: Select Department | F6: Operations
A7: Tenure (Years) | B7: -0.071322781 | C7: =D7 -> 1 | D7: 1 | E7: Select Country | F7: Canada
A8: Time in Role (Years) | B8: 0.21601685 | C8: =D8 -> 1 | D8: 1 | E8: Select Performance Tier | F8: Needs Improvement
A9: Compa-Ratio | B9: 0.29290994 | C9: =D9 -> 0.85 | D9: 0.85 | E9: Select Job Level | F9: Entry
A10: Promotion in Last 2 Years | B10: 0.7957323 | C10: =IF(D10="No",1,0) -> 1 | D10: No | E10: Select Work Setup | F10: Office
A11: Months Since Salary Increase | B11: 0.020052706 | C11: =D11 -> 18 | D11: 18
A12: Engagement Score | B12: -0.033631459 | C12: =D12 -> 2 | D12: 2
A13: Absence Days | B13: 0.01834052 | C13: =D13 -> 12 | D13: 12
A14: Manager Tenure (Years) | B14: 0.031426791 | C14: =D14 -> 1 | D14: 1
A15: Overtime | B15: -0.57903445 | C15: =IF(D15="Yes", 0, 1) -> 0 | D15: Yes
A16: Training Hours | B16: 0.0054640706 | C16: =D16 -> 10 | D16: 10
A17: Gender_Female | B17: 0.4844651 | C17: =IF(D17="Female", 1, 0) -> 1 | D17: Female
A18: Perf_Needs_Improvement | B18: 0.12909761 | C18: =IF($F$8="Yes", 1, 0) -> 0
A19: Perf_Exceeds | B19: -0.081116629 | C19: =IF($F$8="Yes", 1, 0) -> 0
A20: Perf_Outstanding | B20: -0.23588423 | C20: =IF($F$8="Yes", 1, 0) -> 0
A21: Job_Entry | B21: 0.41391554 | C21: =IF($F$9="Yes", 1, 0) -> 0
A22: Job_Manager | B22: 0.15038906 | C22: =IF($F$9="Yes", 1, 0) -> 0
A23: Job_Senior | B23: -0.28926721 | C23: =IF($F$9="Yes", 1, 0) -> 0
A24: Job_Senior_Manager | B24: 0.088629935 | C24: =IF($F$9="Yes", 1, 0) -> 0
A25: Dept_Claims | B25: 0.066576659 | C25: =IF($F$6="Yes", 1, 0) -> 0
A26: Dept_Finance | B26: 0.052375185 | C26: =IF($F$6="Finance", 1, 0) -> 0
A27: Dept_HR | B27: 0.13098757 | C27: =IF($F$6="Yes", 1, 0) -> 0
A28: Dept_IT | B28: 0.087598149 | C28: =IF($F$6="Yes", 1, 0) -> 0
A29: Dept_Marketing | B29: -0.14789576 | C29: =IF($F$6="Yes", 1, 0) -> 0
A30: Dept_Sales | B30: 0.072181123 | C30: =IF($F$6="Yes", 1, 0) -> 0
A31: Dept_Underwriting | B31: -0.42022541 | C31: =IF($F$6="Yes", 1, 0) -> 0
A32: Country_Canada | B32: 1.0586403 | C32: =IF($F$7="Yes", 1, 0) -> 0
A33: Country_Germany | B33: 0.16068222 | C33: =IF($F$7="Yes", 1, 0) -> 0
A34: Country_Ireland | B34: 0.85182842 | C34: =IF($F$7="Yes", 1, 0) -> 0
A35: Country_Singapore | B35: 0.38441114 | C35: =IF($F$7="Yes", 1, 0) -> 0
A36: Country_US | B36: 0.12074148 | C36: =IF($F$7="Yes", 1, 0) -> 0
A37: Work_Office | B37: 0.0082859418 | C37: =IF($F$11="Yes", 1, 0) -> 0
A38: Work_Remote | B38: 0.0014628186 | C38: =IF($F$11="Yes", 1, 0) -> 0
A45: 🎛️ Creating the Live Individual Calculator Tab
A46: To make this user-friendly for managers, create a new tab in your Excel file laid out exactly like this.
A47: Layout Structure:
...

Sheet Insights & Takeaways
A1: Key findings
A3: 1. Department
A5: IT contributes the largest proportion of leavers (17%), followed by Sales and Operations (16% each).
A6: However, Finance has the highest departmental attrition rate at 18%, followed by HR (16.3%) and Claims (16.1%).
A7: This indicates that the volume of leavers and the rate of attrition tell different stories, with Finance warranting particular attention.
A9: 2. Age
A11: Employees aged 32–45 account for 60% of all leavers, making this the largest leaver population.
A12: Their attrition rate is 16.2%.
A13: The 60–73 group has a high apparent attrition rate of 50%, but represents only 1% of leavers, so this should be treated cautiously because of the small population.
A15: 3. Gender
A17: Males represent 58% of leavers, compared with 42% females.
A18: However, the female attrition rate is 17.3%, compared with 12.5% for males.
... A45: The descriptive analysis indicates an overall attrition rate of 14.9%, with 149 leavers averaging 4.5 years' tenure. While IT contributes the largest proportion of leavers, Finance has the highest departmental attrition rate. Attrition also appears elevated among female employees, early-tenure employees, entry-level employees and employees in Canada. The analysis highlights a number of populations that warrant further investigation, particularly where high attrition rates are not reflected in the overall volume of leavers.

Sheet Executive Insights & Recommenda
A1: Executive summary
A3: Overall attrition is 14.9%, with 149 leavers from a workforce of 1,000. Attrition is concentrated in specific workforce populations rather than being evenly distributed. The analysis identifies engagement, reward positioning and time since salary increase as recurring factors associated with higher attrition.
A8: Area | B8: Key Finding | C8: Attrition
A9: Engagaement | B9: Low engagement employees have significantly higher attrition | C9: 0.38
A10: Reward Positioning | B10: Employees with compa-ratio <0.85 show elevated attrition | C10: 0.22
A11: Salary Progression | B11: Employees with 24+ months since salary increase show elevated attrition | C11: 0.24
A12: Promotion | B12: Employees without promotion have higher attrition | C12: 18% vs 8%
A15: Where is attrition concentrated?
A16: Population | B16: Attrition | C16: Overall | D16: Difference
A17: Canada | B17: 0.28 | C17: 0.149 | D17: +13.1pp
A18: Entry level | B18: 0.21 | C18: 0.149 | D18: +6.1pp
A19: Finance | B19: 0.18 | C19: 0.149 | D19: +3.1pp
A20: Female | B20: 0.173 | C20: 0.149 | D20: +2.4pp
A21: HR | B21: 0.163 | C21: 0.149 | D21: +1.4pp
A22: Claims | B22: 0.161 | C22: 0.149 | D22: +1.2pp
A25: Diagnostic findings
A27: Potential drivers / associated factors
A29: Engagement - Low-engagement employees have an attrition rate of 38%, compared with 10% among very-high engagement employees.
A33: Reward - Employees with a compa-ratio below 0.85 have 22% attrition, compared with 13% for employees at 0.85–<1.00.
A37: Salary progression - Employees who have gone 24+ months since their last salary increase have 24% attrition, compared with 12% among those receiving an increase within 6–12 months.
A41: Promotion - Employees who have not received a promotion have 18% attrition, compared with 8% among employees who have received one.
A45: Overtime - Employees working overtime have 21% attrition, compared with 12% among employees who do not.
A49: Intersection analysis
A51: Finance
A52: Finance has 18% overall attrition.
A53: Low engagement → 57%
A54: Compa-ratio <0.85 → 54%
... A82: Recommendations
A83: Finding | B83: Recommended action
A84: Low engagement associated with high attrition | B84: Conduct targeted engagement analysis and focus groups to understand key drivers
A85: Low compa-ratio associated with higher attrition | B85: Review compensation positioning and market competitiveness for high-risk populations
A86: 24+ months since salary increase | B86: Review salary progression and pay-review history for affected employees
A87: Entry-level attrition elevated | B87: Review early-career development, progression and reward pathways
A88: Finance attrition elevated | B88: Conduct deeper Finance workforce review
A89: Female attrition higher | B89: Investigate progression, reward positioning and engagement by gender
A90: Canada attrition significantly elevated | B90: Conduct country-level workforce review to identify local drivers
A93: Limitations
A94: Analytical considerations
A95: The analysis identifies patterns and associations within the workforce data but does not establish causation. Some segments contain relatively small populations, meaning high attrition percentages should be interpreted cautiously. Further analysis, including statistical testing, qualitative feedback and stakeholder validation, would help confirm the underlying drivers of attrition.
A99: INSIGHTS
...

Sheet Diagnostic Analysis
A2: Overall diagnostic factors | N2: Attrition | O2: Yes | S2: Attrition | T2: Yes
A4: Engagement score | B4: Employee | C4: Leavers | D4: Attrition % | F4: Attrition is substantially higher among employees with lower engagement scores, reaching 38% among the Low engagement group compared with 10% among Very High engagement employees. This suggests engagement may be an important factor associated with employee retention and warrants further investigation. | N4: Department | O4: No of Leavers | S4: No of Leavers | T4: Column Labels
A5: High | B5: 417 | C5: 48 | D5: 0.11510791 | N5: Entry | O5: 0.17449664 | S5: Department | T5: Less than 1 year | U5: 1-<2 years | V5: 2-<5 years | W5: 5-<10 years | X5: 10-<15 years | Y5: Grand Total
A6: Low | B6: 40 | C6: 15 | D6: 0.375 | N6: Manager | O6: 0.15436242 | S6: Entry | T6: 0.0067114094 | U6: 0.033557047 | V6: 0.080536913 | W6: 0.053691275 | X6: 0 | Y6: 0.17449664
A7: Moderate | B7: 408 | C7: 73 | D7: 0.17892157 | N7: Professional | O7: 0.3557047 | S7: Manager | T7: 0.0067114094 | U7: 0.020134228 | V7: 0.033557047 | W7: 0.080536913 | X7: 0.013422819 | Y7: 0.15436242
A8: Very high | B8: 135 | C8: 13 | D8: 0.096296296 | N8: Senior | O8: 0.24161074 | S8: Professional | T8: 0.020134228 | U8: 0.040268456 | V8: 0.19463087 | W8: 0.087248322 | X8: 0.013422819 | Y8: 0.3557047
A9: Grand Total | B9: 1000 | C9: 149 | D9: 0.149 | N9: Senior Manager | O9: 0.073825503 | S9: Senior | T9: 0.026845638 | U9: 0.013422819 | V9: 0.10067114 | W9: 0.087248322 | X9: 0.013422819 | Y9: 0.24161074
N10: Grand Total | O10: 1 | S10: Senior Manager | T10: 0.0067114094 | U10: 0.013422819 | V10: 0.033557047 | W10: 0.020134228 | X10: 0 | Y10: 0.073825503
S11: Grand Total | T11: 0.067114094 | U11: 0.12080537 | V11: 0.44295302 | W11: 0.32885906 | X11: 0.040268456 | Y11: 1
A13: Compa ratio | B13: Employee | C13: Leavers | D13: Attrition % | F13: Attrition is highest among employees with a compa-ratio below 0.85 (22%), but is also elevated among employees at 1.15+ (19%), suggesting a non-linear relationship between compensation positioning and attrition that warrants further investigation.
A14: 0.85-<1.00 | B14: 412 | C14: 54 | D14: 0.13106796
A15: 1.00-<1.15 | B15: 395 | C15: 56 | D15: 0.14177215 | N15: Attrition | O15: Yes
A16: 1.15+ | B16: 102 | C16: 19 | D16: 0.18627451
A17: less than 0.85 | B17: 91 | C17: 20 | D17: 0.21978022 | N17: Department | O17: No of Leavers
A18: Grand Total | B18: 1000 | C18: 149 | D18: 0.149 | N18: 1-<2 years | O18: 0.12080537
N19: Sales | O19: 0.033557047
N20: IT | O20: 0.026845638
N21: Finance | O21: 0.020134228
A22: Salary increase recency | B22: Employee | C22: Leavers | D22: Attrition % | F22: Employees who have gone 24 months or more since their last salary increase have the highest attrition rate at 24%, compared with 12–14% among employees whose last increase occurred within the previous 24 months. This suggests salary increase recency may be associated with retention. | N22: Operations | O22: 0.020134228
A23: <6 months | B23: 118 | C23: 16 | D23: 0.13559322 | N23: HR | O23: 0.0067114094
A24: 13-24 months | B24: 496 | C24: 65 | D24: 0.13104839 | N24: Underwriting | O24: 0.0067114094
A25: 24+ months | B25: 173 | C25: 42 | D25: 0.24277457 | N25: Claims | O25: 0.0067114094
A26: 6-12 months | B26: 213 | C26: 26 | D26: 0.12206573 | N26: 10-<15 years | O26: 0.040268456
A27: Grand Total | B27: 1000 | C27: 149 | D27: 0.149 | N27: Sales | O27: 0.013422819
N28: Claims | O28: 0.013422819
N29: Operations | O29: 0.0067114094
N30: HR | O30: 0.0067114094
A31: Promotion | B31: Employee | C31: Leavers | D31: Attrition % | F31: Employees who had not received a promotion had an attrition rate of 18%, compared with 8% among employees who had been promoted. This indicates a strong association between recent promotion status and retention, although further analysis would be required to understand the underlying drivers. | N31: 2-<5 years | O31: 0.44295302
A32: No | B32: 719 | C32: 127 | D32: 0.17663421 | N32: IT | O32: 0.073825503
A33: Yes | B33: 281 | C33: 22 | D33: 0.078291815 | N33: Sales | O33: 0.060402685
A34: Grand Total | B34: 1000 | C34: 149 | D34: 0.149 | N34: Finance | O34: 0.053691275
N35: Operations | O35: 0.053691275
N36: HR | O36: 0.053691275
N37: Claims | O37: 0.053691275
A38: Performance | B38: Employee | C38: Leavers | D38: Attrition % | F38: Attrition varies relatively little across performance categories, ranging from 13% among Outstanding performers to 17% among employees rated Needs Improvement. Performance therefore does not appear to be a major differentiator of attrition in this analysis. | N38: Underwriting | O38: 0.046979866
A39: Exceeds Expectations | B39: 282 | C39: 41 | D39: 0.14539007 | N39: Marketing | O39: 0.046979866
A40: Meets Expectations | B40: 567 | C40: 86 | D40: 0.15167549 | N40: 5-<10 years | O40: 0.32885906
A41: Needs Improvement | B41: 72 | C41: 12 | D41: 0.16666667 | N41: Finance | O41: 0.080536913
A42: Outstanding | B42: 79 | C42: 10 | D42: 0.12658228 | N42: Operations | O42: 0.067114094
A43: Grand Total | B43: 1000 | C43: 149 | D43: 0.149 | N43: Claims | O43: 0.053691275
...

Sheet Analytical Pivots
A1: LEAVERS PROFILE
A3: Row Labels | B3: Headcount | D3: Attrition | E3: Yes | H3: Attrition | I3: No
A4: No | B4: 851
A5: Grand Total | B5: 851 | D5: Average of Tenure (Years) | H5: Row Labels | I5: Headcount
D6: 4.5073826 | H6: Female | I6: 0.49001175
H7: Male | I7: 0.50998825
E8: Attrition | F8: Yes | H8: Grand Total | I8: 1
A9: Attrition | B9: No of Leavers
A10: Yes | B10: 149 | E10: No of Leavers | F10: Average of Tenure (Years)
A11: Grand Total | B11: 149 | E11: Female | F11: 4.3689655
E12: Male | F12: 4.7016129 | H12: Attrition | I12: Yes
E13: Grand Total | F13: 4.5073826
A14: No of Leavers | B14: No of Employees | C14: Count of Employee ID | H14: Attrition | I14: No of Leavers
A15: No | B15: 851 | C15: 0.851 | H15: Female | I15: 0.58389262
A16: Yes | B16: 149 | C16: 0.149 | H16: Male | I16: 0.41610738
A17: Grand Total | B17: 1000 | C17: 1 | H17: Grand Total | I17: 1
A19: Attrition | B19: Yes
A21: Department | B21: No of Leavers
A22: IT | B22: 0.16778523
A23: Sales | B23: 0.16107383
A24: Operations | B24: 0.16107383
A25: Finance | B25: 0.15436242
A26: Claims | B26: 0.13422819
A27: HR | B27: 0.087248322
A28: Underwriting | B28: 0.073825503
A29: Marketing | B29: 0.060402685
A30: Grand Total | B30: 1
A35: Attrition | B35: Yes
A37: Business Unit | B37: No of Leavers | C37: %
A38: Commercial | B38: 33 | C38: 0.22147651
A39: Corporate | B39: 23 | C39: 0.15436242
A40: Insurance | B40: 31 | C40: 0.20805369
A41: Operations | B41: 24 | C41: 0.16107383
A42: People | B42: 13 | C42: 0.087248322
A43: Technology | B43: 25 | C43: 0.16778523
A44: Grand Total | B44: 149 | C44: 1
A49: Attrition | B49: Yes
A51: Country | B51: No of Leavers | C51: %
A52: Canada | B52: 21 | C52: 0.1409396
A53: Germany | B53: 8 | C53: 0.053691275
...

Sheet Diagonistic Pivots
A1: Engagement score | B1: Attrition %
A2: Low | B2: 0.375
A3: Moderate | B3: 0.17892157
A4: High | B4: 0.11510791
A5: Very high | B5: 0.096296296
A6: Grand Total | B6: 0.149
A11: Employee | B11: Column Labels
A12: Engagement score | B12: Stayers | C12: Leavers
A13: High | B13: 369 | C13: 48
A14: Low | B14: 25 | C14: 15
A15: Moderate | B15: 335 | C15: 73
A16: Very high | B16: 122 | C16: 13
A17: Grand Total | B17: 851 | C17: 149
A24: Compa-ratio | B24: Attrition %
A25: less than 0.85 | B25: 0.21978022
A26: 1.15+ | B26: 0.18627451
A27: 1.00-<1.15 | B27: 0.14177215
A28: 0.85-<1.00 | B28: 0.13106796
A29: Grand Total | B29: 0.149
A33: Salary recency increase | B33: Attrition %
A34: 24+ months | B34: 0.24277457
A35: <6 months | B35: 0.13559322
A36: 13-24 months | B36: 0.13104839
A37: 6-12 months | B37: 0.12206573
A38: Grand Total | B38: 0.149
A41: Promotion | B41: Attrition %
A42: No | B42: 0.17663421
A43: Yes | B43: 0.078291815
A44: Grand Total | B44: 0.149
A48: Performance ratings | B48: Attrition %
A49: Needs Improvement | B49: 0.16666667
A50: Meets Expectations | B50: 0.15167549
A51: Exceeds Expectations | B51: 0.14539007
A52: Outstanding | B52: 0.12658228
A53: Grand Total | B53: 0.149
A56: Overtime | B56: Attrition %
A57: Yes | B57: 0.20735786
A58: No | B58: 0.12410842
A59: Grand Total | B59: 0.149

Sheet Dashboard Pivots
A1: LEAVERS PROFILE
A3: Row Labels | B3: Headcount | D3: Attrition | E3: Yes | H3: Attrition | I3: No
A4: No | B4: 851
A5: Grand Total | B5: 851 | D5: Average of Tenure (Years) | H5: Row Labels | I5: Headcount
D6: 4.5073826 | H6: Female | I6: 0.49001175
H7: Male | I7: 0.50998825
E8: Attrition | F8: Yes | H8: Grand Total | I8: 1
A9: Attrition | B9: No of Leavers
A10: Yes | B10: 149 | E10: No of Leavers | F10: Average of Tenure (Years)
A11: Grand Total | B11: 149 | E11: Female | F11: 4.3689655
E12: Male | F12: 4.7016129 | H12: Attrition | I12: Yes
E13: Grand Total | F13: 4.5073826
A14: No of Leavers | B14: No of Employees | C14: Count of Employee ID | H14: Attrition | I14: No of Leavers
A15: No | B15: 851 | C15: 0.851 | H15: Female | I15: 0.58389262
A16: Yes | B16: 149 | C16: 0.149 | H16: Male | I16: 0.41610738
A17: Grand Total | B17: 1000 | C17: 1 | H17: Grand Total | I17: 1
A19: Attrition | B19: Yes
A21: Department | B21: No of Leavers
A22: IT | B22: 0.16778523
A23: Sales | B23: 0.16107383
A24: Operations | B24: 0.16107383
A25: Finance | B25: 0.15436242
A26: Claims | B26: 0.13422819
A27: HR | B27: 0.087248322
A28: Underwriting | B28: 0.073825503
A29: Marketing | B29: 0.060402685
A30: Grand Total | B30: 1
A35: Attrition | B35: Yes
A37: Business Unit | B37: %
A38: Commercial | B38: 0.22147651
A39: Corporate | B39: 0.15436242
A40: Insurance | B40: 0.20805369
A41: Operations | B41: 0.16107383
A42: People | B42: 0.087248322
A43: Technology | B43: 0.16778523
A44: Grand Total | B44: 1
A49: Attrition | B49: Yes
A51: Country | B51: %
A52: UK | B52: 0.40268456
A53: US | B53: 0.24832215
...

Sheet Predictive Model
A1: Employee ID | B1: Gender | C1: Department | D1: Business Unit | E1: Country | F1: Job Level | G1: Age | H1: Tenure (Years) | I1: Time in Role (Years) | J1: Compa-Ratio | K1: Performance Rating | L1: Promotion in Last 2 Years | M1: Months Since Salary Increase | N1: Engagement Score | O1: Absence Days | P1: Manager Tenure (Years) | Q1: Working Arrangement | R1: Overtime | S1: Training Hours | T1: Leaver flag | U1: Gender_Female | V1: Perf_Needs_Improvement | W1: Perf_Exceeds | X1: Perf_Outstanding | Y1: Job_Entry | Z1: Job_Manager | AA1: Job_Senior | AB1: Job_Senior_Manager | AC1: Dept_Claims | AD1: Dept_Finance | AE1: Dept_HR | AF1: Dept_IT | AG1: Dept_Marketing | AH1: Dept_Sales | AI1: Dept_Underwriting | AJ1: Country_Canada | AK1: Country_Germany | AL1: Country_Ireland | AM1: Country_Singapore | AN1: Country_US | AO1: Work_Office | AP1: Work_Remote | AQ1: Column1
A2: E0001 | B2: =VLOOKUP(EmployeeData3[[#This Row],[Employee ID]],GenderData[#All],2,FALSE) -> Female | C2: Sales | D2: Commercial | E2: UK | F2: Professional | G2: 39 | H2: 1.9 | I2: 1.9 | J2: 1.12 | K2: Meets Expectations | L2: No | M2: 19 | N2: 86 | O2: 2 | P2: 5.2 | Q2: Remote | R2: No | S2: 44 | T2: 0 | U2: =IF(EmployeeData3[[#This Row],[Gender]]="Female",1,0) -> 1 | V2: =IF(EmployeeData3[[#This Row],[Performance Rating]]="Needs Improvement",1,0) -> 0 | W2: =IF(EmployeeData3[[#This Row],[Performance Rating]]="Exceeds Expectations",1,0) -> 0 | X2: =IF(EmployeeData3[[#This Row],[Performance Rating]]="Outstanding",1,0) -> 0 | Y2: =IF(EmployeeData3[[#This Row],[Job Level]]="Entry",1,0) -> 0 | Z2: =IF(EmployeeData3[[#This Row],[Job Level]]="Manager",1,0) -> 0 | AA2: =IF(EmployeeData3[[#This Row],[Job Level]]="Senior",1,0) -> 0 | AB2: =IF(EmployeeData3[[#This Row],[Job Level]]="Senior Manager",1,0) -> 0 | AC2: =IF(EmployeeData3[[#This Row],[Department]]="Claims",1,0) -> 0 | AD2: =IF(EmployeeData3[[#This Row],[Department]]="Finance",1,0) -> 0 | AE2: =IF(EmployeeData3[[#This Row],[Department]]="HR",1,0) -> 0 | AF2: =IF(EmployeeData3[[#This Row],[Department]]="IT",1,0) -> 0 | AG2: =IF(EmployeeData3[[#This Row],[Department]]="Marketing",1,0) -> 0 | AH2: =IF(EmployeeData3[[#This Row],[Department]]="Sales",1,0) -> 1 | AI2: =IF(EmployeeData3[[#This Row],[Department]]="Underwriting",1,0) -> 0 | AJ2: =IF(EmployeeData3[[#This Row],[Country]]="Canada",1,0) -> 0 | AK2: =IF(EmployeeData3[[#This Row],[Country]]="Germany",1,0) -> 0 | AL2: =IF(EmployeeData3[[#This Row],[Country]]="Ireland",1,0) -> 0 | AM2: =IF(EmployeeData3[[#This Row],[Country]]="Singapore",1,0) -> 0 | AN2: =IF(EmployeeData3[[#This Row],[Country]]="US",1,0) -> 0 | AO2: =IF(EmployeeData3[[#This Row],[Working Arrangement]]="Office",1,0) -> 0 | AP2: =IF(EmployeeData3[[#This Row],[Working Arrangement]]="Remote",1,0) -> 1 | AQ2: ='Logistics Regression'!#REF! + SUMPRODUCT(B2:J2, 'Logistics Regression'!#REF!) -> #REF!
A3: E0002 | B3: =VLOOKUP(EmployeeData3[[#This Row],[Employee ID]],GenderData[#All],2,FALSE) -> Male | C3: Claims | D3: Insurance | E3: Germany | F3: Senior | G3: 32 | H3: 2 | I3: 2 | J3: 0.95 | K3: Meets Expectations | L3: No | M3: 8 | N3: 91 | O3: 2 | P3: 2.8 | Q3: Hybrid | R3: No | S3: 0 | T3: 0 | U3: =IF(EmployeeData3[[#This Row],[Gender]]="Female",1,0) -> 0 | V3: =IF(EmployeeData3[[#This Row],[Performance Rating]]="Needs Improvement",1,0) -> 0 | W3: =IF(EmployeeData3[[#This Row],[Performance Rating]]="Exceeds Expectations",1,0) -> 0 | X3: =IF(EmployeeData3[[#This Row],[Performance Rating]]="Outstanding",1,0) -> 0 | Y3: =IF(EmployeeData3[[#This Row],[Job Level]]="Entry",1,0) -> 0 | Z3: =IF(EmployeeData3[[#This Row],[Job Level]]="Manager",1,0) -> 0 | AA3: =IF(EmployeeData3[[#This Row],[Job Level]]="Senior",1,0) -> 1 | AB3: =IF(EmployeeData3[[#This Row],[Job Level]]="Senior Manager",1,0) -> 0 | AC3: =IF(EmployeeData3[[#This Row],[Department]]="Claims",1,0) -> 1 | AD3: =IF(EmployeeData3[[#This Row],[Department]]="Finance",1,0) -> 0 | AE3: =IF(EmployeeData3[[#This Row],[Department]]="HR",1,0) -> 0 | AF3: =IF(EmployeeData3[[#This Row],[Department]]="IT",1,0) -> 0 | AG3: =IF(EmployeeData3[[#This Row],[Department]]="Marketing",1,0) -> 0 | AH3: =IF(EmployeeData3[[#This Row],[Department]]="Sales",1,0) -> 0 | AI3: =IF(EmployeeData3[[#This Row],[Department]]="Underwriting",1,0) -> 0 | AJ3: =IF(EmployeeData3[[#This Row],[Country]]="Canada",1,0) -> 0 | AK3: =IF(EmployeeData3[[#This Row],[Country]]="Germany",1,0) -> 1 | AL3: =IF(EmployeeData3[[#This Row],[Country]]="Ireland",1,0) -> 0 | AM3: =IF(EmployeeData3[[#This Row],[Country]]="Singapore",1,0) -> 0 | AN3: =IF(EmployeeData3[[#This Row],[Country]]="US",1,0) -> 0 | AO3: =IF(EmployeeData3[[#This Row],[Working Arrangement]]="Office",1,0) -> 0 | AP3: =IF(EmployeeData3[[#This Row],[Working Arrangement]]="Remote",1,0) -> 0 | AQ3: ='Logistics Regression'!#REF! + SUMPRODUCT(B3:J3, 'Logistics Regression'!#REF!) -> #REF!
A4: E0003 | B4: =VLOOKUP(EmployeeData3[[#This Row],[Employee ID]],GenderData[#All],2,FALSE) -> Male | C4: Marketing | D4: Commercial | E4: UK | F4: Manager | G4: 21 | H4: 7.2 | I4: 1.2 | J4: 0.89 | K4: Exceeds Expectations | L4: No | M4: 31 | N4: 55 | O4: 3 | P4: 0.5 | Q4: Remote | R4: Yes | S4: 37 | T4: 0 | U4: =IF(EmployeeData3[[#This Row],[Gender]]="Female",1,0) -> 0 | V4: =IF(EmployeeData3[[#This Row],[Performance Rating]]="Needs Improvement",1,0) -> 0 | W4: =IF(EmployeeData3[[#This Row],[Performance Rating]]="Exceeds Expectations",1,0) -> 1 | X4: =IF(EmployeeData3[[#This Row],[Performance Rating]]="Outstanding",1,0) -> 0 | Y4: =IF(EmployeeData3[[#This Row],[Job Level]]="Entry",1,0) -> 0 | Z4: =IF(EmployeeData3[[#This Row],[Job Level]]="Manager",1,0) -> 1 | AA4: =IF(EmployeeData3[[#This Row],[Job Level]]="Senior",1,0) -> 0 | AB4: =IF(EmployeeData3[[#This Row],[Job Level]]="Senior Manager",1,0) -> 0 | AC4: =IF(EmployeeData3[[#This Row],[Department]]="Claims",1,0) -> 0 | AD4: =IF(EmployeeData3[[#This Row],[Department]]="Finance",1,0) -> 0 | AE4: =IF(EmployeeData3[[#This Row],[Department]]="HR",1,0) -> 0 | AF4: =IF(EmployeeData3[[#This Row],[Department]]="IT",1,0) -> 0 | AG4: =IF(EmployeeData3[[#This Row],[Department]]="Marketing",1,0) -> 1 | AH4: =IF(EmployeeData3[[#This Row],[Department]]="Sales",1,0) -> 0 | AI4: =IF(EmployeeData3[[#This Row],[Department]]="Underwriting",1,0) -> 0 | AJ4: =IF(EmployeeData3[[#This Row],[Country]]="Canada",1,0) -> 0 | AK4: =IF(EmployeeData3[[#This Row],[Country]]="Germany",1,0) -> 0 | AL4: =IF(EmployeeData3[[#This Row],[Country]]="Ireland",1,0) -> 0 | AM4: =IF(EmployeeData3[[#This Row],[Country]]="Singapore",1,0) -> 0 | AN4: =IF(EmployeeData3[[#This Row],[Country]]="US",1,0) -> 0 | AO4: =IF(EmployeeData3[[#This Row],[Working Arrangement]]="Office",1,0) -> 0 | AP4: =IF(EmployeeData3[[#This Row],[Working Arrangement]]="Remote",1,0) -> 1 | AQ4: ='Logistics Regression'!#REF! + SUMPRODUCT(B4:J4, 'Logistics Regression'!#REF!) -> #REF!
A5: E0004 | B5: =VLOOKUP(EmployeeData3[[#This Row],[Employee ID]],GenderData[#All],2,FALSE) -> Female | C5: Operations | D5: Operations | E5: Singapore | F5: Senior | G5: 48 | H5: 2 | I5: 2 | J5: 0.99 | K5: Exceeds Expectations | L5: No | M5: 35 | N5: 78 | O5: 3 | P5: 2.3 | Q5: Remote | R5: No | S5: 27 | T5: 0 | U5: =IF(EmployeeData3[[#This Row],[Gender]]="Female",1,0) -> 1 | V5: =IF(EmployeeData3[[#This Row],[Performance Rating]]="Needs Improvement",1,0) -> 0 | W5: =IF(EmployeeData3[[#This Row],[Performance Rating]]="Exceeds Expectations",1,0) -> 1 | X5: =IF(EmployeeData3[[#This Row],[Performance Rating]]="Outstanding",1,0) -> 0 | Y5: =IF(EmployeeData3[[#This Row],[Job Level]]="Entry",1,0) -> 0 | Z5: =IF(EmployeeData3[[#This Row],[Job Level]]="Manager",1,0) -> 0 | AA5: =IF(EmployeeData3[[#This Row],[Job Level]]="Senior",1,0) -> 1 | AB5: =IF(EmployeeData3[[#This Row],[Job Level]]="Senior Manager",1,0) -> 0 | AC5: =IF(EmployeeData3[[#This Row],[Department]]="Claims",1,0) -> 0 | AD5: =IF(EmployeeData3[[#This Row],[Department]]="Finance",1,0) -> 0 | AE5: =IF(EmployeeData3[[#This Row],[Department]]="HR",1,0) -> 0 | AF5: =IF(EmployeeData3[[#This Row],[Department]]="IT",1,0) -> 0 | AG5: =IF(EmployeeData3[[#This Row],[Department]]="Marketing",1,0) -> 0 | AH5: =IF(EmployeeData3[[#This Row],[Department]]="Sales",1,0) -> 0 | AI5: =IF(EmployeeData3[[#This Row],[Department]]="Underwriting",1,0) -> 0 | AJ5: =IF(EmployeeData3[[#This Row],[Country]]="Canada",1,0) -> 0 | AK5: =IF(EmployeeData3[[#This Row],[Country]]="Germany",1,0) -> 0 | AL5: =IF(EmployeeData3[[#This Row],[Country]]="Ireland",1,0) -> 0 | AM5: =IF(EmployeeData3[[#This Row],[Country]]="Singapore",1,0) -> 1 | AN5: =IF(EmployeeData3[[#This Row],[Country]]="US",1,0) -> 0 | AO5: =IF(EmployeeData3[[#This Row],[Working Arrangement]]="Office",1,0) -> 0 | AP5: =IF(EmployeeData3[[#This Row],[Working Arrangement]]="Remote",1,0) -> 1 | AQ5: ='Logistics Regression'!#REF! + SUMPRODUCT(B5:J5, 'Logistics Regression'!#REF!) -> #REF!
A6: E0005 | B6: =VLOOKUP(EmployeeData3[[#This Row],[Employee ID]],GenderData[#All],2,FALSE) -> Male | C6: Finance | D6: Corporate | E6: US | F6: Manager | G6: 23 | H6: 3.9 | I6: 2.3 | J6: 1.04 | K6: Meets Expectations | L6: No | M6: 16 | N6: 81 | O6: 5 | P6: 4.3 | Q6: Hybrid | R6: Yes | S6: 35 | T6: 0 | U6: =IF(EmployeeData3[[#This Row],[Gender]]="Female",1,0) -> 0 | V6: =IF(EmployeeData3[[#This Row],[Performance Rating]]="Needs Improvement",1,0) -> 0 | W6: =IF(EmployeeData3[[#This Row],[Performance Rating]]="Exceeds Expectations",1,0) -> 0 | X6: =IF(EmployeeData3[[#This Row],[Performance Rating]]="Outstanding",1,0) -> 0 | Y6: =IF(EmployeeData3[[#This Row],[Job Level]]="Entry",1,0) -> 0 | Z6: =IF(EmployeeData3[[#This Row],[Job Level]]="Manager",1,0) -> 1 | AA6: =IF(EmployeeData3[[#This Row],[Job Level]]="Senior",1,0) -> 0 | AB6: =IF(EmployeeData3[[#This Row],[Job Level]]="Senior Manager",1,0) -> 0 | AC6: =IF(EmployeeData3[[#This Row],[Department]]="Claims",1,0) -> 0 | AD6: =IF(EmployeeData3[[#This Row],[Department]]="Finance",1,0) -> 1 | AE6: =IF(EmployeeData3[[#This Row],[Department]]="HR",1,0) -> 0 | AF6: =IF(EmployeeData3[[#This Row],[Department]]="IT",1,0) -> 0 | AG6: =IF(EmployeeData3[[#This Row],[Department]]="Marketing",1,0) -> 0 | AH6: =IF(EmployeeData3[[#This Row],[Department]]="Sales",1,0) -> 0 | AI6: =IF(EmployeeData3[[#This Row],[Department]]="Underwriting",1,0) -> 0 | AJ6: =IF(EmployeeData3[[#This Row],[Country]]="Canada",1,0) -> 0 | AK6: =IF(EmployeeData3[[#This Row],[Country]]="Germany",1,0) -> 0 | AL6: =IF(EmployeeData3[[#This Row],[Country]]="Ireland",1,0) -> 0 | AM6: =IF(EmployeeData3[[#This Row],[Country]]="Singapore",1,0) -> 0 | AN6: =IF(EmployeeData3[[#This Row],[Country]]="US",1,0) -> 1 | AO6: =IF(EmployeeData3[[#This Row],[Working Arrangement]]="Office",1,0) -> 0 | AP6: =IF(EmployeeData3[[#This Row],[Working Arrangement]]="Remote",1,0) -> 0 | AQ6: ='Logistics Regression'!#REF! + SUMPRODUCT(B6:J6, 'Logistics Regression'!#REF!) -> #REF!
A7: E0006 | B7: =VLOOKUP(EmployeeData3[[#This Row],[Employee ID]],GenderData[#All],2,FALSE) -> Female | C7: Finance | D7: Corporate | E7: Germany | F7: Senior | G7: 43 | H7: 2.1 | I7: 1.9 | J7: 0.88 | K7: Meets Expectations | L7: No | M7: 11 | N7: 80 | O7: 9 | P7: 3.4 | Q7: Hybrid | R7: No | S7: 17 | T7: 0 | U7: =IF(EmployeeData3[[#This Row],[Gender]]="Female",1,0) -> 1 | V7: =IF(EmployeeData3[[#This Row],[Performance Rating]]="Needs Improvement",1,0) -> 0 | W7: =IF(EmployeeData3[[#This Row],[Performance Rating]]="Exceeds Expectations",1,0) -> 0 | X7: =IF(EmployeeData3[[#This Row],[Performance Rating]]="Outstanding",1,0) -> 0 | Y7: =IF(EmployeeData3[[#This Row],[Job Level]]="Entry",1,0) -> 0 | Z7: =IF(EmployeeData3[[#This Row],[Job Level]]="Manager",1,0) -> 0 | AA7: =IF(EmployeeData3[[#This Row],[Job Level]]="Senior",1,0) -> 1 | AB7: =IF(EmployeeData3[[#This Row],[Job Level]]="Senior Manager",1,0) -> 0 | AC7: =IF(EmployeeData3[[#This Row],[Department]]="Claims",1,0) -> 0 | AD7: =IF(EmployeeData3[[#This Row],[Department]]="Finance",1,0) -> 1 | AE7: =IF(EmployeeData3[[#This Row],[Department]]="HR",1,0) -> 0 | AF7: =IF(EmployeeData3[[#This Row],[Department]]="IT",1,0) -> 0 | AG7: =IF(EmployeeData3[[#This Row],[Department]]="Marketing",1,0) -> 0 | AH7: =IF(EmployeeData3[[#This Row],[Department]]="Sales",1,0) -> 0 | AI7: =IF(EmployeeData3[[#This Row],[Department]]="Underwriting",1,0) -> 0 | AJ7: =IF(EmployeeData3[[#This Row],[Country]]="Canada",1,0) -> 0 | AK7: =IF(EmployeeData3[[#This Row],[Country]]="Germany",1,0) -> 1 | AL7: =IF(EmployeeData3[[#This Row],[Country]]="Ireland",1,0) -> 0 | AM7: =IF(EmployeeData3[[#This Row],[Country]]="Singapore",1,0) -> 0 | AN7: =IF(EmployeeData3[[#This Row],[Country]]="US",1,0) -> 0 | AO7: =IF(EmployeeData3[[#This Row],[Working Arrangement]]="Office",1,0) -> 0 | AP7: =IF(EmployeeData3[[#This Row],[Working Arrangement]]="Remote",1,0) -> 0 | AQ7: ='Logistics Regression'!#REF! + SUMPRODUCT(B7:J7, 'Logistics Regression'!#REF!) -> #REF!
A8: E0007 | B8: =VLOOKUP(EmployeeData3[[#This Row],[Employee ID]],GenderData[#All],2,FALSE) -> Female | C8: IT | D8: Technology | E8: UK | F8: Senior | G8: 38 | H8: 0.3 | I8: 0.3 | J8: 0.97 | K8: Meets Expectations | L8: No | M8: 14 | N8: 78 | O8: 2 | P8: 3.7 | Q8: Office | R8: Yes | S8: 3 | T8: 0 | U8: =IF(EmployeeData3[[#This Row],[Gender]]="Female",1,0) -> 1 | V8: =IF(EmployeeData3[[#This Row],[Performance Rating]]="Needs Improvement",1,0) -> 0 | W8: =IF(EmployeeData3[[#This Row],[Performance Rating]]="Exceeds Expectations",1,0) -> 0 | X8: =IF(EmployeeData3[[#This Row],[Performance Rating]]="Outstanding",1,0) -> 0 | Y8: =IF(EmployeeData3[[#This Row],[Job Level]]="Entry",1,0) -> 0 | Z8: =IF(EmployeeData3[[#This Row],[Job Level]]="Manager",1,0) -> 0 | AA8: =IF(EmployeeData3[[#This Row],[Job Level]]="Senior",1,0) -> 1 | AB8: =IF(EmployeeData3[[#This Row],[Job Level]]="Senior Manager",1,0) -> 0 | AC8: =IF(EmployeeData3[[#This Row],[Department]]="Claims",1,0) -> 0 | AD8: =IF(EmployeeData3[[#This Row],[Department]]="Finance",1,0) -> 0 | AE8: =IF(EmployeeData3[[#This Row],[Department]]="HR",1,0) -> 0 | AF8: =IF(EmployeeData3[[#This Row],[Department]]="IT",1,0) -> 1 | AG8: =IF(EmployeeData3[[#This Row],[Department]]="Marketing",1,0) -> 0 | AH8: =IF(EmployeeData3[[#This Row],[Department]]="Sales",1,0) -> 0 | AI8: =IF(EmployeeData3[[#This Row],[Department]]="Underwriting",1,0) -> 0 | AJ8: =IF(EmployeeData3[[#This Row],[Country]]="Canada",1,0) -> 0 | AK8: =IF(EmployeeData3[[#This Row],[Country]]="Germany",1,0) -> 0 | AL8: =IF(EmployeeData3[[#This Row],[Country]]="Ireland",1,0) -> 0 | AM8: =IF(EmployeeData3[[#This Row],[Country]]="Singapore",1,0) -> 0 | AN8: =IF(EmployeeData3[[#This Row],[Country]]="US",1,0) -> 0 | AO8: =IF(EmployeeData3[[#This Row],[Working Arrangement]]="Office",1,0) -> 1 | AP8: =IF(EmployeeData3[[#This Row],[Working Arrangement]]="Remote",1,0) -> 0 | AQ8: ='Logistics Regression'!#REF! + SUMPRODUCT(B8:J8, 'Logistics Regression'!#REF!) -> #REF!
A9: E0008 | B9: =VLOOKUP(EmployeeData3[[#This Row],[Employee ID]],GenderData[#All],2,FALSE) -> Male | C9: Underwriting | D9: Insurance | E9: UK | F9: Manager | G9: 57 | H9: 7 | I9: 3.1 | J9: 1 | K9: Needs Improvement | L9: Yes | M9: 22 | N9: 51 | O9: 9 | P9: 4.6 | Q9: Hybrid | R9: No | S9: 31 | T9: 0 | U9: =IF(EmployeeData3[[#This Row],[Gender]]="Female",1,0) -> 0 | V9: =IF(EmployeeData3[[#This Row],[Performance Rating]]="Needs Improvement",1,0) -> 1 | W9: =IF(EmployeeData3[[#This Row],[Performance Rating]]="Exceeds Expectations",1,0) -> 0 | X9: =IF(EmployeeData3[[#This Row],[Performance Rating]]="Outstanding",1,0) -> 0 | Y9: =IF(EmployeeData3[[#This Row],[Job Level]]="Entry",1,0) -> 0 | Z9: =IF(EmployeeData3[[#This Row],[Job Level]]="Manager",1,0) -> 1 | AA9: =IF(EmployeeData3[[#This Row],[Job Level]]="Senior",1,0) -> 0 | AB9: =IF(EmployeeData3[[#This Row],[Job Level]]="Senior Manager",1,0) -> 0 | AC9: =IF(EmployeeData3[[#This Row],[Department]]="Claims",1,0) -> 0 | AD9: =IF(EmployeeData3[[#This Row],[Department]]="Finance",1,0) -> 0 | AE9: =IF(EmployeeData3[[#This Row],[Department]]="HR",1,0) -> 0 | AF9: =IF(EmployeeData3[[#This Row],[Department]]="IT",1,0) -> 0 | AG9: =IF(EmployeeData3[[#This Row],[Department]]="Marketing",1,0) -> 0 | AH9: =IF(EmployeeData3[[#This Row],[Department]]="Sales",1,0) -> 0 | AI9: =IF(EmployeeData3[[#This Row],[Department]]="Underwriting",1,0) -> 1 | AJ9: =IF(EmployeeData3[[#This Row],[Country]]="Canada",1,0) -> 0 | AK9: =IF(EmployeeData3[[#This Row],[Country]]="Germany",1,0) -> 0 | AL9: =IF(EmployeeData3[[#This Row],[Country]]="Ireland",1,0) -> 0 | AM9: =IF(EmployeeData3[[#This Row],[Country]]="Singapore",1,0) -> 0 | AN9: =IF(EmployeeData3[[#This Row],[Country]]="US",1,0) -> 0 | AO9: =IF(EmployeeData3[[#This Row],[Working Arrangement]]="Office",1,0) -> 0 | AP9: =IF(EmployeeData3[[#This Row],[Working Arrangement]]="Remote",1,0) -> 0 | AQ9: ='Logistics Regression'!#REF! + SUMPRODUCT(B9:J9, 'Logistics Regression'!#REF!) -> #REF!
A10: E0009 | B10: =VLOOKUP(EmployeeData3[[#This Row],[Employee ID]],GenderData[#All],2,FALSE) -> Male | C10: Operations | D10: Operations | E10: Canada | F10: Professional | G10: 47 | H10: 4.1 | I10: 4.1 | J10: 1.01 | K10: Exceeds Expectations | L10: No | M10: 28 | N10: 63 | O10: 8 | P10: 1.1 | Q10: Hybrid | R10: Yes | S10: 13 | T10: 0 | U10: =IF(EmployeeData3[[#This Row],[Gender]]="Female",1,0) -> 0 | V10: =IF(EmployeeData3[[#This Row],[Performance Rating]]="Needs Improvement",1,0) -> 0 | W10: =IF(EmployeeData3[[#This Row],[Performance Rating]]="Exceeds Expectations",1,0) -> 1 | X10: =IF(EmployeeData3[[#This Row],[Performance Rating]]="Outstanding",1,0) -> 0 | Y10: =IF(EmployeeData3[[#This Row],[Job Level]]="Entry",1,0) -> 0 | Z10: =IF(EmployeeData3[[#This Row],[Job Level]]="Manager",1,0) -> 0 | AA10: =IF(EmployeeData3[[#This Row],[Job Level]]="Senior",1,0) -> 0 | AB10: =IF(EmployeeData3[[#This Row],[Job Level]]="Senior Manager",1,0) -> 0 | AC10: =IF(EmployeeData3[[#This Row],[Department]]="Claims",1,0) -> 0 | AD10: =IF(EmployeeData3[[#This Row],[Department]]="Finance",1,0) -> 0 | AE10: =IF(EmployeeData3[[#This Row],[Department]]="HR",1,0) -> 0 | AF10: =IF(EmployeeData3[[#This Row],[Department]]="IT",1,0) -> 0 | AG10: =IF(EmployeeData3[[#This Row],[Department]]="Marketing",1,0) -> 0 | AH10: =IF(EmployeeData3[[#This Row],[Department]]="Sales",1,0) -> 0 | AI10: =IF(EmployeeData3[[#This Row],[Department]]="Underwriting",1,0) -> 0 | AJ10: =IF(EmployeeData3[[#This Row],[Country]]="Canada",1,0) -> 1 | AK10: =IF(EmployeeData3[[#This Row],[Country]]="Germany",1,0) -> 0 | AL10: =IF(EmployeeData3[[#This Row],[Country]]="Ireland",1,0) -> 0 | AM10: =IF(EmployeeData3[[#This Row],[Country]]="Singapore",1,0) -> 0 | AN10: =IF(EmployeeData3[[#This Row],[Country]]="US",1,0) -> 0 | AO10: =IF(EmployeeData3[[#This Row],[Working Arrangement]]="Office",1,0) -> 0 | AP10: =IF(EmployeeData3[[#This Row],[Working Arrangement]]="Remote",1,0) -> 0 | AQ10: ='Logistics Regression'!#REF! + SUMPRODUCT(B10:J10, 'Logistics Regression'!#REF!) -> #REF!
A11: E0010 | B11: =VLOOKUP(EmployeeData3[[#This Row],[Employee ID]],GenderData[#All],2,FALSE) -> Male | C11: Marketing | D11: Commercial | E11: US | F11: Professional | G11: 33 | H11: 5.6 | I11: 5.6 | J11: 1.01 | K11: Meets Expectations | L11: No | M11: 21 | N11: 55 | O11: 8 | P11: 4.7 | Q11: Hybrid | R11: No | S11: 7 | T11: 1 | U11: =IF(EmployeeData3[[#This Row],[Gender]]="Female",1,0) -> 0 | V11: =IF(EmployeeData3[[#This Row],[Performance Rating]]="Needs Improvement",1,0) -> 0 | W11: =IF(EmployeeData3[[#This Row],[Performance Rating]]="Exceeds Expectations",1,0) -> 0 | X11: =IF(EmployeeData3[[#This Row],[Performance Rating]]="Outstanding",1,0) -> 0 | Y11: =IF(EmployeeData3[[#This Row],[Job Level]]="Entry",1,0) -> 0 | Z11: =IF(EmployeeData3[[#This Row],[Job Level]]="Manager",1,0) -> 0 | AA11: =IF(EmployeeData3[[#This Row],[Job Level]]="Senior",1,0) -> 0 | AB11: =IF(EmployeeData3[[#This Row],[Job Level]]="Senior Manager",1,0) -> 0 | AC11: =IF(EmployeeData3[[#This Row],[Department]]="Claims",1,0) -> 0 | AD11: =IF(EmployeeData3[[#This Row],[Department]]="Finance",1,0) -> 0 | AE11: =IF(EmployeeData3[[#This Row],[Department]]="HR",1,0) -> 0 | AF11: =IF(EmployeeData3[[#This Row],[Department]]="IT",1,0) -> 0 | AG11: =IF(EmployeeData3[[#This Row],[Department]]="Marketing",1,0) -> 1 | AH11: =IF(EmployeeData3[[#This Row],[Department]]="Sales",1,0) -> 0 | AI11: =IF(EmployeeData3[[#This Row],[Department]]="Underwriting",1,0) -> 0 | AJ11: =IF(EmployeeData3[[#This Row],[Country]]="Canada",1,0) -> 0 | AK11: =IF(EmployeeData3[[#This Row],[Country]]="Germany",1,0) -> 0 | AL11: =IF(EmployeeData3[[#This Row],[Country]]="Ireland",1,0) -> 0 | AM11: =IF(EmployeeData3[[#This Row],[Country]]="Singapore",1,0) -> 0 | AN11: =IF(EmployeeData3[[#This Row],[Country]]="US",1,0) -> 1 | AO11: =IF(EmployeeData3[[#This Row],[Working Arrangement]]="Office",1,0) -> 0 | AP11: =IF(EmployeeData3[[#This Row],[Working Arrangement]]="Remote",1,0) -> 0 | AQ11: ='Logistics Regression'!#REF! + SUMPRODUCT(B11:J11, 'Logistics Regression'!#REF!) -> #REF!
A12: E0011 | B12: =VLOOKUP(EmployeeData3[[#This Row],[Employee ID]],GenderData[#All],2,FALSE) -> Female | C12: IT | D12: Technology | E12: UK | F12: Professional | G12: 32 | H12: 0.9 | I12: 0.9 | J12: 1.03 | K12: Exceeds Expectations | L12: No | M12: 17 | N12: 70 | O12: 5 | P12: 8.4 | Q12: Hybrid | R12: No | S12: 8 | T12: 1 | U12: =IF(EmployeeData3[[#This Row],[Gender]]="Female",1,0) -> 1 | V12: =IF(EmployeeData3[[#This Row],[Performance Rating]]="Needs Improvement",1,0) -> 0 | W12: =IF(EmployeeData3[[#This Row],[Performance Rating]]="Exceeds Expectations",1,0) -> 1 | X12: =IF(EmployeeData3[[#This Row],[Performance Rating]]="Outstanding",1,0) -> 0 | Y12: =IF(EmployeeData3[[#This Row],[Job Level]]="Entry",1,0) -> 0 | Z12: =IF(EmployeeData3[[#This Row],[Job Level]]="Manager",1,0) -> 0 | AA12: =IF(EmployeeData3[[#This Row],[Job Level]]="Senior",1,0) -> 0 | AB12: =IF(EmployeeData3[[#This Row],[Job Level]]="Senior Manager",1,0) -> 0 | AC12: =IF(EmployeeData3[[#This Row],[Department]]="Claims",1,0) -> 0 | AD12: =IF(EmployeeData3[[#This Row],[Department]]="Finance",1,0) -> 0 | AE12: =IF(EmployeeData3[[#This Row],[Department]]="HR",1,0) -> 0 | AF12: =IF(EmployeeData3[[#This Row],[Department]]="IT",1,0) -> 1 | AG12: =IF(EmployeeData3[[#This Row],[Department]]="Marketing",1,0) -> 0 | AH12: =IF(EmployeeData3[[#This Row],[Department]]="Sales",1,0) -> 0 | AI12: =IF(EmployeeData3[[#This Row],[Department]]="Underwriting",1,0) -> 0 | AJ12: =IF(EmployeeData3[[#This Row],[Country]]="Canada",1,0) -> 0 | AK12: =IF(EmployeeData3[[#This Row],[Country]]="Germany",1,0) -> 0 | AL12: =IF(EmployeeData3[[#This Row],[Country]]="Ireland",1,0) -> 0 | AM12: =IF(EmployeeData3[[#This Row],[Country]]="Singapore",1,0) -> 0 | AN12: =IF(EmployeeData3[[#This Row],[Country]]="US",1,0) -> 0 | AO12: =IF(EmployeeData3[[#This Row],[Working Arrangement]]="Office",1,0) -> 0 | AP12: =IF(EmployeeData3[[#This Row],[Working Arrangement]]="Remote",1,0) -> 0 | AQ12: ='Logistics Regression'!#REF! + SUMPRODUCT(B12:J12, 'Logistics Regression'!#REF!) -> #REF!
A13: E0012 | B13: =VLOOKUP(EmployeeData3[[#This Row],[Employee ID]],GenderData[#All],2,FALSE) -> Female | C13: Claims | D13: Insurance | E13: UK | F13: Senior Manager | G13: 52 | H13: 2.6 | I13: 2.4 | J13: 0.91 | K13: Exceeds Expectations | L13: No | M13: 29 | N13: 80 | O13: 2 | P13: 2.1 | Q13: Hybrid | R13: No | S13: 31 | T13: 0 | U13: =IF(EmployeeData3[[#This Row],[Gender]]="Female",1,0) -> 1 | V13: =IF(EmployeeData3[[#This Row],[Performance Rating]]="Needs Improvement",1,0) -> 0 | W13: =IF(EmployeeData3[[#This Row],[Performance Rating]]="Exceeds Expectations",1,0) -> 1 | X13: =IF(EmployeeData3[[#This Row],[Performance Rating]]="Outstanding",1,0) -> 0 | Y13: =IF(EmployeeData3[[#This Row],[Job Level]]="Entry",1,0) -> 0 | Z13: =IF(EmployeeData3[[#This Row],[Job Level]]="Manager",1,0) -> 0 | AA13: =IF(EmployeeData3[[#This Row],[Job Level]]="Senior",1,0) -> 0 | AB13: =IF(EmployeeData3[[#This Row],[Job Level]]="Senior Manager",1,0) -> 1 | AC13: =IF(EmployeeData3[[#This Row],[Department]]="Claims",1,0) -> 1 | AD13: =IF(EmployeeData3[[#This Row],[Department]]="Finance",1,0) -> 0 | AE13: =IF(EmployeeData3[[#This Row],[Department]]="HR",1,0) -> 0 | AF13: =IF(EmployeeData3[[#This Row],[Department]]="IT",1,0) -> 0 | AG13: =IF(EmployeeData3[[#This Row],[Department]]="Marketing",1,0) -> 0 | AH13: =IF(EmployeeData3[[#This Row],[Department]]="Sales",1,0) -> 0 | AI13: =IF(EmployeeData3[[#This Row],[Department]]="Underwriting",1,0) -> 0 | AJ13: =IF(EmployeeData3[[#This Row],[Country]]="Canada",1,0) -> 0 | AK13: =IF(EmployeeData3[[#This Row],[Country]]="Germany",1,0) -> 0 | AL13: =IF(EmployeeData3[[#This Row],[Country]]="Ireland",1,0) -> 0 | AM13: =IF(EmployeeData3[[#This Row],[Country]]="Singapore",1,0) -> 0 | AN13: =IF(EmployeeData3[[#This Row],[Country]]="US",1,0) -> 0 | AO13: =IF(EmployeeData3[[#This Row],[Working Arrangement]]="Office",1,0) -> 0 | AP13: =IF(EmployeeData3[[#This Row],[Working Arrangement]]="Remote",1,0) -> 0 | AQ13: ='Logistics Regression'!#REF! + SUMPRODUCT(B13:J13, 'Logistics Regression'!#REF!) -> #REF!
